{
  "errors": [
    {
      "test": "unittest.loader._FailedTest.test_prueba_tests",
      "traceback": "Traceback (most recent call last):\n  File \"C:\\Users\\Jorge\\AppData\\Local\\Programs\\Python\\Python312\\Lib\\unittest\\case.py\", line 58, in testPartExecutor\n    yield\n  File \"C:\\Users\\Jorge\\AppData\\Local\\Programs\\Python\\Python312\\Lib\\unittest\\case.py\", line 636, in run\n    self._callTestMethod(testMethod)\n    ^^^^^^^^^^^^^^^^^\n  File \"C:\\Users\\Jorge\\AppData\\Local\\Programs\\Python\\Python312\\Lib\\unittest\\case.py\", line 589, in _callTestMethod\n    if method() is not None:\n    ^^^^^^^^^^^^^^^^^\n  File \"C:\\Users\\Jorge\\AppData\\Local\\Programs\\Python\\Python312\\Lib\\unittest\\loader.py\", line 33, in testFailure\n    raise self._exception\n    ^^^^^^^^^^^^^^^^^\nImportError: Failed to import test module: test_prueba_tests\nTraceback (most recent call last):\n  File \"C:\\Users\\Jorge\\AppData\\Local\\Programs\\Python\\Python312\\Lib\\unittest\\loader.py\", line 137, in loadTestsFromName\n    module = __import__(module_name)\n             ^^^^^^^^^^^^^^^^^^^^^^^\n  File \"c:\\users\\jorge\\documents\\github\\g85.2024.t05.eg2\\src\\unittest\\python\\test_prueba_tests.py\", line 3, in <module>\n    from prueba import sum\nModuleNotFoundError: No module named 'prueba'\n\n"
    }
  ],
  "failures": [],
  "tests-run": 1
}